[2024-12-07T03:27:35.173-0300] {local_task_job_runner.py:123} INFO - ::group::Pre task execution logs
[2024-12-07T03:27:35.182-0300] {taskinstance.py:2613} INFO - Dependencies all met for dep_context=non-requeueable deps ti=<TaskInstance: hiring_dynamic_pipeline.decide_datasets manual__2024-12-07T06:26:56.979469+00:00 [queued]>
[2024-12-07T03:27:35.188-0300] {taskinstance.py:2613} INFO - Dependencies all met for dep_context=requeueable deps ti=<TaskInstance: hiring_dynamic_pipeline.decide_datasets manual__2024-12-07T06:26:56.979469+00:00 [queued]>
[2024-12-07T03:27:35.188-0300] {taskinstance.py:2866} INFO - Starting attempt 1 of 2
[2024-12-07T03:27:35.243-0300] {taskinstance.py:2889} INFO - Executing <Task(BranchPythonOperator): decide_datasets> on 2024-12-07 06:26:56.979469+00:00
[2024-12-07T03:27:35.249-0300] {standard_task_runner.py:72} INFO - Started process 43579 to run task
[2024-12-07T03:27:35.252-0300] {standard_task_runner.py:104} INFO - Running: ['airflow', 'tasks', 'run', 'hiring_dynamic_pipeline', 'decide_datasets', 'manual__2024-12-07T06:26:56.979469+00:00', '--job-id', '44', '--raw', '--subdir', 'DAGS_FOLDER/dag_dynamic.py', '--cfg-path', '/tmp/tmpvm2as7rk']
[2024-12-07T03:27:35.253-0300] {standard_task_runner.py:105} INFO - Job 44: Subtask decide_datasets
[2024-12-07T03:27:35.320-0300] {task_command.py:467} INFO - Running <TaskInstance: hiring_dynamic_pipeline.decide_datasets manual__2024-12-07T06:26:56.979469+00:00 [running]> on host crisu-VivoBook-S14-X411UF
[2024-12-07T03:27:35.446-0300] {taskinstance.py:3132} INFO - Exporting env vars: AIRFLOW_CTX_DAG_OWNER='airflow' AIRFLOW_CTX_DAG_ID='hiring_dynamic_pipeline' AIRFLOW_CTX_TASK_ID='decide_datasets' AIRFLOW_CTX_EXECUTION_DATE='2024-12-07T06:26:56.979469+00:00' AIRFLOW_CTX_TRY_NUMBER='1' AIRFLOW_CTX_DAG_RUN_ID='manual__2024-12-07T06:26:56.979469+00:00'
[2024-12-07T03:27:35.447-0300] {logging_mixin.py:190} INFO - Task instance is in running state
[2024-12-07T03:27:35.447-0300] {logging_mixin.py:190} INFO -  Previous state of the Task instance: queued
[2024-12-07T03:27:35.447-0300] {logging_mixin.py:190} INFO - Current task name:decide_datasets state:running start_date:2024-12-07 06:27:35.183234+00:00
[2024-12-07T03:27:35.447-0300] {logging_mixin.py:190} INFO - Dag name:hiring_dynamic_pipeline and current dag run status:running
[2024-12-07T03:27:35.447-0300] {taskinstance.py:731} INFO - ::endgroup::
[2024-12-07T03:27:35.448-0300] {baseoperator.py:416} WARNING - BranchPythonOperator.execute cannot be called outside TaskInstance!
[2024-12-07T03:27:35.448-0300] {taskinstance.py:3311} ERROR - Task failed with exception
Traceback (most recent call last):
  File "/home/crisu/miniconda3/envs/lab13.1/lib/python3.9/site-packages/airflow/models/taskinstance.py", line 767, in _execute_task
    result = _execute_callable(context=context, **execute_callable_kwargs)
  File "/home/crisu/miniconda3/envs/lab13.1/lib/python3.9/site-packages/airflow/models/taskinstance.py", line 733, in _execute_callable
    return ExecutionCallableRunner(
  File "/home/crisu/miniconda3/envs/lab13.1/lib/python3.9/site-packages/airflow/utils/operator_helpers.py", line 252, in run
    return self.func(*args, **kwargs)
  File "/home/crisu/miniconda3/envs/lab13.1/lib/python3.9/site-packages/airflow/models/baseoperator.py", line 417, in wrapper
    return func(self, *args, **kwargs)
  File "/home/crisu/miniconda3/envs/lab13.1/lib/python3.9/site-packages/airflow/operators/python.py", line 274, in execute
    return self.do_branch(context, super().execute(context))
  File "/home/crisu/miniconda3/envs/lab13.1/lib/python3.9/site-packages/airflow/models/baseoperator.py", line 417, in wrapper
    return func(self, *args, **kwargs)
  File "/home/crisu/miniconda3/envs/lab13.1/lib/python3.9/site-packages/airflow/operators/python.py", line 238, in execute
    return_value = self.execute_callable()
  File "/home/crisu/miniconda3/envs/lab13.1/lib/python3.9/site-packages/airflow/operators/python.py", line 256, in execute_callable
    return runner.run(*self.op_args, **self.op_kwargs)
  File "/home/crisu/miniconda3/envs/lab13.1/lib/python3.9/site-packages/airflow/utils/operator_helpers.py", line 252, in run
    return self.func(*args, **kwargs)
  File "/home/crisu/Universidad/MDS7202-Primavera2024/Lab 13 - Airflow/dags/dag_dynamic.py", line 28, in decide_which_datasets
    if execution_date < cutoff_date:
TypeError: '<' not supported between instances of 'str' and 'datetime.datetime'
[2024-12-07T03:27:35.454-0300] {logging_mixin.py:190} INFO - Task instance in failure state
[2024-12-07T03:27:35.454-0300] {logging_mixin.py:190} INFO - Task start:2024-12-07 06:27:35.183234+00:00 end:2024-12-07 06:27:35.453970+00:00 duration:0.270736
[2024-12-07T03:27:35.454-0300] {logging_mixin.py:190} INFO - Task:<Task(BranchPythonOperator): decide_datasets> dag:<DAG: hiring_dynamic_pipeline> dagrun:<DagRun hiring_dynamic_pipeline @ 2024-12-07 06:26:56.979469+00:00: manual__2024-12-07T06:26:56.979469+00:00, state:running, queued_at: 2024-12-07 06:26:58.026518+00:00. externally triggered: True>
[2024-12-07T03:27:35.455-0300] {logging_mixin.py:190} INFO - Failure caused by '<' not supported between instances of 'str' and 'datetime.datetime'
[2024-12-07T03:27:35.455-0300] {taskinstance.py:1225} INFO - Marking task as UP_FOR_RETRY. dag_id=hiring_dynamic_pipeline, task_id=decide_datasets, run_id=manual__2024-12-07T06:26:56.979469+00:00, execution_date=20241207T062656, start_date=20241207T062735, end_date=20241207T062735
[2024-12-07T03:27:35.506-0300] {taskinstance.py:340} INFO - ::group::Post task execution logs
[2024-12-07T03:27:35.507-0300] {standard_task_runner.py:124} ERROR - Failed to execute job 44 for task decide_datasets ('<' not supported between instances of 'str' and 'datetime.datetime'; 43579)
Traceback (most recent call last):
  File "/home/crisu/miniconda3/envs/lab13.1/lib/python3.9/site-packages/airflow/task/task_runner/standard_task_runner.py", line 117, in _start_by_fork
    ret = args.func(args, dag=self.dag)
  File "/home/crisu/miniconda3/envs/lab13.1/lib/python3.9/site-packages/airflow/cli/cli_config.py", line 49, in command
    return func(*args, **kwargs)
  File "/home/crisu/miniconda3/envs/lab13.1/lib/python3.9/site-packages/airflow/utils/cli.py", line 116, in wrapper
    return f(*args, **kwargs)
  File "/home/crisu/miniconda3/envs/lab13.1/lib/python3.9/site-packages/airflow/cli/commands/task_command.py", line 483, in task_run
    task_return_code = _run_task_by_selected_method(args, _dag, ti)
  File "/home/crisu/miniconda3/envs/lab13.1/lib/python3.9/site-packages/airflow/cli/commands/task_command.py", line 256, in _run_task_by_selected_method
    return _run_raw_task(args, ti)
  File "/home/crisu/miniconda3/envs/lab13.1/lib/python3.9/site-packages/airflow/cli/commands/task_command.py", line 341, in _run_raw_task
    return ti._run_raw_task(
  File "/home/crisu/miniconda3/envs/lab13.1/lib/python3.9/site-packages/airflow/utils/session.py", line 97, in wrapper
    return func(*args, session=session, **kwargs)
  File "/home/crisu/miniconda3/envs/lab13.1/lib/python3.9/site-packages/airflow/models/taskinstance.py", line 3005, in _run_raw_task
    return _run_raw_task(
  File "/home/crisu/miniconda3/envs/lab13.1/lib/python3.9/site-packages/airflow/models/taskinstance.py", line 273, in _run_raw_task
    TaskInstance._execute_task_with_callbacks(
  File "/home/crisu/miniconda3/envs/lab13.1/lib/python3.9/site-packages/airflow/models/taskinstance.py", line 3159, in _execute_task_with_callbacks
    result = self._execute_task(context, task_orig)
  File "/home/crisu/miniconda3/envs/lab13.1/lib/python3.9/site-packages/airflow/models/taskinstance.py", line 3183, in _execute_task
    return _execute_task(self, context, task_orig)
  File "/home/crisu/miniconda3/envs/lab13.1/lib/python3.9/site-packages/airflow/models/taskinstance.py", line 767, in _execute_task
    result = _execute_callable(context=context, **execute_callable_kwargs)
  File "/home/crisu/miniconda3/envs/lab13.1/lib/python3.9/site-packages/airflow/models/taskinstance.py", line 733, in _execute_callable
    return ExecutionCallableRunner(
  File "/home/crisu/miniconda3/envs/lab13.1/lib/python3.9/site-packages/airflow/utils/operator_helpers.py", line 252, in run
    return self.func(*args, **kwargs)
  File "/home/crisu/miniconda3/envs/lab13.1/lib/python3.9/site-packages/airflow/models/baseoperator.py", line 417, in wrapper
    return func(self, *args, **kwargs)
  File "/home/crisu/miniconda3/envs/lab13.1/lib/python3.9/site-packages/airflow/operators/python.py", line 274, in execute
    return self.do_branch(context, super().execute(context))
  File "/home/crisu/miniconda3/envs/lab13.1/lib/python3.9/site-packages/airflow/models/baseoperator.py", line 417, in wrapper
    return func(self, *args, **kwargs)
  File "/home/crisu/miniconda3/envs/lab13.1/lib/python3.9/site-packages/airflow/operators/python.py", line 238, in execute
    return_value = self.execute_callable()
  File "/home/crisu/miniconda3/envs/lab13.1/lib/python3.9/site-packages/airflow/operators/python.py", line 256, in execute_callable
    return runner.run(*self.op_args, **self.op_kwargs)
  File "/home/crisu/miniconda3/envs/lab13.1/lib/python3.9/site-packages/airflow/utils/operator_helpers.py", line 252, in run
    return self.func(*args, **kwargs)
  File "/home/crisu/Universidad/MDS7202-Primavera2024/Lab 13 - Airflow/dags/dag_dynamic.py", line 28, in decide_which_datasets
    if execution_date < cutoff_date:
TypeError: '<' not supported between instances of 'str' and 'datetime.datetime'
[2024-12-07T03:27:35.546-0300] {local_task_job_runner.py:266} INFO - Task exited with return code 1
[2024-12-07T03:27:35.566-0300] {taskinstance.py:3895} INFO - 0 downstream tasks scheduled from follow-on schedule check
[2024-12-07T03:27:35.566-0300] {local_task_job_runner.py:245} INFO - ::endgroup::
